<?xml version="1.0" encoding="utf-8"?>
<!-- This URDF was automatically created by SolidWorks to URDF Exporter! Originally created by Stephen Brawner (brawner@gmail.com) 
     Commit Version: 1.6.0-4-g7f85cfe  Build Version: 1.6.7995.38578
     For more information, please see http://wiki.ros.org/sw_urdf_exporter -->
<robot
  name="Robby_v1">
  <link
    name="world" />
  <joint
    name="world_to_base_link"
    type="fixed">
    <origin
      xyz="0 0 0"
      rpy="0 0 0" />
    <parent
      link="world" />
    <child
      link="base_link" />
  </joint>
  <link
    name="base_link">
    <inertial>
      <origin
        xyz="-0.0202853583615552 -0.0035672102008257 0.0384224210186663"
        rpy="0 0 0" />
      <mass
        value="2.2668069894461" />
      <inertia
        ixx="0.00935572177906156"
        ixy="7.8725799589304E-09"
        ixz="0.00155513248174071"
        iyy="0.013073444250648"
        iyz="-4.07017227501552E-08"
        izz="0.017855946897602" />
    </inertial>
    <visual>
      <origin
        xyz="0 0 0"
        rpy="0 0 0" />
      <geometry>
        <mesh
          filename="file:///home/aditya/ros2_ws/ITQ_robby/src/robby_description/meshes/base_link.STL" />
      </geometry>
      <material
        name="">
        <color
          rgba="0.854901960784314 0.349019607843137 0.349019607843137 1" />
      </material>
    </visual>
    <collision>
      <origin
        xyz="0 0 0"
        rpy="0 0 0" />
      <geometry>
        <mesh
          filename="file:///home/aditya/ros2_ws/ITQ_robby/src/robby_description/meshes/base_link.STL" />
      </geometry>
    </collision>
  </link>
  <link
    name="front_left_steer">
    <inertial>
      <origin
        xyz="0.00013064414965952 -0.00712793384390203 -0.099167907470358"
        rpy="0 0 0" />
      <mass
        value="0.251781132487417" />
      <inertia
        ixx="0.00021743551373503"
        ixy="1.36860311137519E-06"
        ixz="5.07501890882553E-07"
        iyy="0.000126727845844533"
        iyz="-3.34647392291718E-05"
        izz="0.000169195629547439" />
    </inertial>
    <visual>
      <origin
        xyz="0 0 0"
        rpy="0 0 0" />
      <geometry>
        <mesh
          filename="file:///home/aditya/ros2_ws/ITQ_robby/src/robby_description/meshes/front_left_steer.STL" />
      </geometry>
      <material
        name="">
        <color
          rgba="0.964705882352941 0.964705882352941 0.952941176470588 1" />
      </material>
    </visual>
    <collision>
      <origin
        xyz="0 0 0"
        rpy="0 0 0" />
      <geometry>
        <mesh
          filename="file:///home/aditya/ros2_ws/ITQ_robby/src/robby_description/meshes/front_left_steer.STL" />
      </geometry>
    </collision>
  </link>
  <joint
    name="f_left_steer"
    type="revolute">
    <origin
      xyz="0.2014 0.16556 0.043251"
      rpy="0 0 0" />
    <parent
      link="base_link" />
    <child
      link="front_left_steer" />
    <axis
      xyz="0 0 1" />
    <limit
      lower="-1.5708"
      upper="1.5708"
      effort="10"
      velocity="10" />
    <dynamics
      damping="0.1"
      friction="0.1" />
  </joint>
  <link
    name="front_left_wheel">
    <inertial>
      <origin
        xyz="-0.000152709268499918 -9.70744181462424E-07 -0.0293675372404548"
        rpy="0 0 0" />
      <mass
        value="0.115832809619263" />
      <inertia
        ixx="0.000133495109179925"
        ixy="7.48118425206543E-14"
        ixz="4.06679703392529E-09"
        iyy="0.000133508500148116"
        iyz="-7.10495622112089E-10"
        izz="0.000211939042658774" />
    </inertial>
    <visual>
      <origin
        xyz="0 0 0"
        rpy="0 0 0" />
      <geometry>
        <mesh
          filename="file:///home/aditya/ros2_ws/ITQ_robby/src/robby_description/meshes/front_left_wheel.STL" />
      </geometry>
      <material
        name="">
        <color
          rgba="0.964705882352941 0.964705882352941 0.952941176470588 1" />
      </material>
    </visual>
    <collision>
      <origin
        xyz="0 0 0"
        rpy="0 0 0" />
      <geometry>
        <mesh
          filename="file:///home/aditya/ros2_ws/ITQ_robby/src/robby_description/meshes/front_left_wheel.STL" />
      </geometry>
    </collision>
  </link>
  <joint
    name="f_leftwheel"
    type="continuous">
    <origin
      xyz="-0.00095872 0.072001 -0.13909"
      rpy="-1.5708 0 0.015251" />
    <parent
      link="front_left_steer" />
    <child
      link="front_left_wheel" />
    <axis
      xyz="0 0 1" />
    <limit
      effort="10"
      velocity="10" />
    <dynamics
      damping="0.1"
      friction="0.1" />
  </joint>
  <link
    name="back_left_steer">
    <inertial>
      <origin
        xyz="9.28109305935038E-05 -0.00712852545284898 -0.101167907583658"
        rpy="0 0 0" />
      <mass
        value="0.251781132525178" />
      <inertia
        ixx="0.000217447487430463"
        ixy="8.87032766970658E-07"
        ixz="3.29855165907127E-07"
        iyy="0.000126715873155165"
        iyz="-3.34669623327156E-05"
        izz="0.000169195628565899" />
    </inertial>
    <visual>
      <origin
        xyz="0 0 0"
        rpy="0 0 0" />
      <geometry>
        <mesh
          filename="file:///home/aditya/ros2_ws/ITQ_robby/src/robby_description/meshes/back_left_steer.STL" />
      </geometry>
      <material
        name="">
        <color
          rgba="0.964705882352941 0.964705882352941 0.952941176470588 1" />
      </material>
    </visual>
    <collision>
      <origin
        xyz="0 0 0"
        rpy="0 0 0" />
      <geometry>
        <mesh
          filename="file:///home/aditya/ros2_ws/ITQ_robby/src/robby_description/meshes/back_left_steer.STL" />
      </geometry>
    </collision>
  </link>
  <joint
    name="b_leftsteer"
    type="revolute">
    <origin
      xyz="-0.20473 0.16556 0.045249"
      rpy="0 0 0" />
    <parent
      link="base_link" />
    <child
      link="back_left_steer" />
    <axis
      xyz="0 0 1" />
    <limit
      lower="-1.5708"
      upper="1.5708"
      effort="10"
      velocity="10" />
    <dynamics
      damping="0.1"
      friction="0.1" />
  </joint>
  <link
    name="back_left_wheel">
    <inertial>
      <origin
        xyz="-0.000152709267548859 -9.71167783692106E-07 -0.029367537223414"
        rpy="0 0 0" />
      <mass
        value="0.115832809709875" />
      <inertia
        ixx="0.000133495109180129"
        ixy="3.73920551199565E-14"
        ixz="4.06679907772533E-09"
        iyy="0.00013350850014901"
        iyz="-7.10484063198117E-10"
        izz="0.000211939042658999" />
    </inertial>
    <visual>
      <origin
        xyz="0 0 0"
        rpy="0 0 0" />
      <geometry>
        <mesh
          filename="file:///home/aditya/ros2_ws/ITQ_robby/src/robby_description/meshes/back_left_wheel.STL" />
      </geometry>
      <material
        name="">
        <color
          rgba="0.964705882352941 0.964705882352941 0.952941176470588 1" />
      </material>
    </visual>
    <collision>
      <origin
        xyz="0 0 0"
        rpy="0 0 0" />
      <geometry>
        <mesh
          filename="file:///home/aditya/ros2_ws/ITQ_robby/src/robby_description/meshes/back_left_wheel.STL" />
      </geometry>
    </collision>
  </link>
  <joint
    name="b_leftwheel"
    type="continuous">
    <origin
      xyz="-0.0005765 0.072005 -0.14109"
      rpy="-1.5708 0 0.0099427" />
    <parent
      link="back_left_steer" />
    <child
      link="back_left_wheel" />
    <axis
      xyz="0 0 1" />
    <limit
      effort="10"
      velocity="10" />
    <dynamics
      damping="0.1"
      friction="0.1" />
  </joint>
  <link
    name="back_right_steer">
    <inertial>
      <origin
        xyz="3.09555434352959E-05 0.00694767645726482 -0.104187659676429"
        rpy="0 0 0" />
      <mass
        value="0.229463165297732" />
      <inertia
        ixx="0.000207384199528673"
        ixy="-7.31104211905778E-07"
        ixz="2.67266326731571E-07"
        iyy="0.000116493139211524"
        iyz="3.35524819424789E-05"
        izz="0.00016798247146896" />
    </inertial>
    <visual>
      <origin
        xyz="0 0 0"
        rpy="0 0 0" />
      <geometry>
        <mesh
          filename="file:///home/aditya/ros2_ws/ITQ_robby/src/robby_description/meshes/back_right_steer.STL" />
      </geometry>
      <material
        name="">
        <color
          rgba="0.964705882352941 0.964705882352941 0.952941176470588 1" />
      </material>
    </visual>
    <collision>
      <origin
        xyz="0 0 0"
        rpy="0 0 0" />
      <geometry>
        <mesh
          filename="file:///home/aditya/ros2_ws/ITQ_robby/src/robby_description/meshes/back_right_steer.STL" />
      </geometry>
    </collision>
  </link>
  <joint
    name="b_rightsteer"
    type="revolute">
    <origin
      xyz="-0.2046 -0.16556 0.04325"
      rpy="0 0 0" />
    <parent
      link="base_link" />
    <child
      link="back_right_steer" />
    <axis
      xyz="0 0 1" />
    <limit
      lower="-1.5708"
      upper="1.5708"
      effort="10"
      velocity="10" />
    <dynamics
      damping="0.1"
      friction="0.1" />
  </joint>
  <link
    name="back_right_wheel">
    <inertial>
      <origin
        xyz="0.000152709273591192 -9.71170377131458E-07 0.0293675371615253"
        rpy="0 0 0" />
      <mass
        value="0.115832810022218" />
      <inertia
        ixx="0.000133495109183378"
        ixy="-3.62614646190951E-14"
        ixz="4.06680017161528E-09"
        iyy="0.000133508500154647"
        iyz="7.10483036587695E-10"
        izz="0.000211939042659798" />
    </inertial>
    <visual>
      <origin
        xyz="0 0 0"
        rpy="0 0 0" />
      <geometry>
        <mesh
          filename="file:///home/aditya/ros2_ws/ITQ_robby/src/robby_description/meshes/back_right_wheel.STL" />
      </geometry>
      <material
        name="">
        <color
          rgba="0.964705882352941 0.964705882352941 0.952941176470588 1" />
      </material>
    </visual>
    <collision>
      <origin
        xyz="0 0 0"
        rpy="0 0 0" />
      <geometry>
        <mesh
          filename="file:///home/aditya/ros2_ws/ITQ_robby/src/robby_description/meshes/back_right_wheel.STL" />
      </geometry>
    </collision>
  </link>
  <joint
    name="b_rightwheel"
    type="continuous">
    <origin
      xyz="-0.00071852 -0.073582 -0.1361"
      rpy="-1.5708 0 -0.0078748" />
    <parent
      link="back_right_steer" />
    <child
      link="back_right_wheel" />
    <axis
      xyz="0 0 -1" />
    <limit
      effort="10"
      velocity="10" />
    <dynamics
      damping="0.1"
      friction="0.1" />
  </joint>
  <link
    name="front_right_steer">
    <inertial>
      <origin
        xyz="4.05809295395687E-05 0.00712901046523262 -0.0991679078738846"
        rpy="0 0 0" />
      <mass
        value="0.251781132690095" />
      <inertia
        ixx="0.000217448974290903"
        ixy="-8.0742080901355E-07"
        ixz="2.95193136544424E-07"
        iyy="0.00012671438820613"
        iyz="3.34672871896417E-05"
        izz="0.000169195626775715" />
    </inertial>
    <visual>
      <origin
        xyz="0 0 0"
        rpy="0 0 0" />
      <geometry>
        <mesh
          filename="file:///home/aditya/ros2_ws/ITQ_robby/src/robby_description/meshes/front_right_steer.STL" />
      </geometry>
      <material
        name="">
        <color
          rgba="0.964705882352941 0.964705882352941 0.952941176470588 1" />
      </material>
    </visual>
    <collision>
      <origin
        xyz="0 0 0"
        rpy="0 0 0" />
      <geometry>
        <mesh
          filename="file:///home/aditya/ros2_ws/ITQ_robby/src/robby_description/meshes/front_right_steer.STL" />
      </geometry>
    </collision>
  </link>
  <joint
    name="f_right_steer"
    type="revolute">
    <origin
      xyz="0.20127 -0.16556 0.04325"
      rpy="0 0 0" />
    <parent
      link="base_link" />
    <child
      link="front_right_steer" />
    <axis
      xyz="0 0 1" />
    <limit
      lower="-1.5708"
      upper="1.5708"
      effort="10"
      velocity="10" />
    <dynamics
      damping="0.1"
      friction="0.1" />
  </joint>
  <link
    name="front_right_wheel">
    <inertial>
      <origin
        xyz="0.00015270927387756 -9.71170482401418E-07 0.0293675371584356"
        rpy="0 0 0" />
      <mass
        value="0.115832810036923" />
      <inertia
        ixx="0.000133495109183675"
        ixy="-3.62122798652987E-14"
        ixz="4.06680027009567E-09"
        iyy="0.000133508500155057"
        iyz="7.10482989342022E-10"
        izz="0.000211939042659837" />
    </inertial>
    <visual>
      <origin
        xyz="0 0 0"
        rpy="0 0 0" />
      <geometry>
        <mesh
          filename="file:///home/aditya/ros2_ws/ITQ_robby/src/robby_description/meshes/front_right_wheel.STL" />
      </geometry>
      <material
        name="">
        <color
          rgba="0.964705882352941 0.964705882352941 0.952941176470588 1" />
      </material>
    </visual>
    <collision>
      <origin
        xyz="0 0 0"
        rpy="0 0 0" />
      <geometry>
        <mesh
          filename="file:///home/aditya/ros2_ws/ITQ_robby/src/robby_description/meshes/front_right_wheel.STL" />
      </geometry>
    </collision>
  </link>
  <joint
    name="f_rightwheel"
    type="continuous">
    <origin
      xyz="-0.00076762 -0.072004 -0.13909"
      rpy="-1.5708 0 -0.0087292" />
    <parent
      link="front_right_steer" />
    <child
      link="front_right_wheel" />
    <axis
      xyz="0 0 -1" />
    <limit
      effort="10"
      velocity="10" />
    <dynamics
      damping="0.1"
      friction="0.1" />
  </joint>
</robot>
