<?xml version="1.0"?>
<robot name="interpack_robot" xmlns:xacro="http://www.ros.org/wiki/xacro">

  <!-- use_sim=true  → Gazebo (digital twin on workstation)  -->
  <!-- use_sim=false → SerialHardwareInterface (real robot on Pi) -->
  <xacro:arg name="use_sim"     default="true"/>
  <xacro:arg name="serial_port" default="/dev/ttyACM0"/>

  <!-- ========== PARAMETER ========== -->
  <xacro:property name="wheel_radius"     value="0.075"/>  <!-- 15cm Durchmesser -->
  <xacro:property name="wheel_width"      value="0.05"/>
  <xacro:property name="wheel_sep_lat"    value="0.70"/>   <!-- Spurweite links-rechts -->
  <xacro:property name="wheel_sep_lon"    value="0.30"/>   <!-- Radstand vorne-hinten -->
  <xacro:property name="chassis_length"   value="0.40"/>
  <xacro:property name="chassis_width"    value="0.76"/>
  <xacro:property name="chassis_height"   value="0.12"/>
  <xacro:property name="chassis_mass"     value="8.0"/>
  <xacro:property name="wheel_mass"       value="0.5"/>

  <!-- Farben -->
  <material name="dark_grey">
    <color rgba="0.2 0.2 0.2 1.0"/>
  </material>
  <material name="orange">
    <color rgba="0.9 0.4 0.1 1.0"/>
  </material>
  <material name="black">
    <color rgba="0.05 0.05 0.05 1.0"/>
  </material>

  <!-- ========== MAKROS ========== -->
  <xacro:macro name="wheel" params="name x_pos y_pos">
    <link name="${name}_wheel_link">
      <visual>
        <origin xyz="0 0 0" rpy="${pi/2} 0 0"/>
        <geometry>
          <cylinder radius="${wheel_radius}" length="${wheel_width}"/>
        </geometry>
        <material name="black"/>
      </visual>
      <collision>
        <origin xyz="0 0 0" rpy="${pi/2} 0 0"/>
        <geometry>
          <cylinder radius="${wheel_radius}" length="${wheel_width}"/>
        </geometry>
      </collision>
      <inertial>
        <mass value="${wheel_mass}"/>
        <inertia
          ixx="${wheel_mass*(3*wheel_radius*wheel_radius + wheel_width*wheel_width)/12}"
          ixy="0" ixz="0"
          iyy="${wheel_mass*(3*wheel_radius*wheel_radius + wheel_width*wheel_width)/12}"
          iyz="0"
          izz="${wheel_mass*wheel_radius*wheel_radius/2}"/>
      </inertial>
    </link>

    <joint name="${name}_wheel_joint" type="continuous">
      <parent link="base_link"/>
      <child  link="${name}_wheel_link"/>
      <origin xyz="${x_pos} ${y_pos} 0" rpy="0 0 0"/>
      <axis xyz="0 1 0"/>
      <dynamics damping="0.1" friction="0.5"/>
    </joint>
  </xacro:macro>

  <!-- ========== LINKS ========== -->

  <!-- Virtueller Bodenkontaktpunkt -->
  <link name="base_footprint"/>

  <joint name="base_footprint_joint" type="fixed">
    <parent link="base_footprint"/>
    <child  link="base_link"/>
    <origin xyz="0 0 ${wheel_radius}" rpy="0 0 0"/>
  </joint>

  <!-- Chassis -->
  <link name="base_link">
    <visual>
      <origin xyz="0 0 0" rpy="0 0 0"/>
      <geometry>
        <box size="${chassis_length} ${chassis_width} ${chassis_height}"/>
      </geometry>
      <material name="dark_grey"/>
    </visual>
    <collision>
      <origin xyz="0 0 0" rpy="0 0 0"/>
      <geometry>
        <box size="${chassis_length} ${chassis_width} ${chassis_height}"/>
      </geometry>
    </collision>
    <inertial>
      <mass value="${chassis_mass}"/>
      <inertia
        ixx="${chassis_mass*(chassis_width*chassis_width + chassis_height*chassis_height)/12}"
        ixy="0" ixz="0"
        iyy="${chassis_mass*(chassis_length*chassis_length + chassis_height*chassis_height)/12}"
        iyz="0"
        izz="${chassis_mass*(chassis_length*chassis_length + chassis_width*chassis_width)/12}"/>
    </inertial>
  </link>

  <!-- 4 Räder -->
  <xacro:wheel name="front_left"  x_pos=" ${wheel_sep_lon/2}" y_pos=" ${wheel_sep_lat/2}"/>
  <xacro:wheel name="front_right" x_pos=" ${wheel_sep_lon/2}" y_pos="-${wheel_sep_lat/2}"/>
  <xacro:wheel name="rear_left"   x_pos="-${wheel_sep_lon/2}" y_pos=" ${wheel_sep_lat/2}"/>
  <xacro:wheel name="rear_right"  x_pos="-${wheel_sep_lon/2}" y_pos="-${wheel_sep_lat/2}"/>

  <!-- ========== ROS2_CONTROL ========== -->
  <ros2_control name="interpack_control" type="system">

    <hardware>
      <xacro:if value="$(arg use_sim)">
        <plugin>gz_ros2_control/GazeboSimSystem</plugin>
      </xacro:if>
      <xacro:unless value="$(arg use_sim)">
        <plugin>robot_hardware/SerialHardwareInterface</plugin>
        <param name="serial_port">$(arg serial_port)</param>
        <param name="baud_rate">115200</param>
        <param name="max_wheel_angular_vel">13.3</param>
      </xacro:unless>
    </hardware>

    <joint name="front_left_wheel_joint">
      <command_interface name="velocity"/>
      <state_interface name="velocity"/>
      <state_interface name="position"/>
    </joint>
    <joint name="front_right_wheel_joint">
      <command_interface name="velocity"/>
      <state_interface name="velocity"/>
      <state_interface name="position"/>
    </joint>
    <joint name="rear_left_wheel_joint">
      <command_interface name="velocity"/>
      <state_interface name="velocity"/>
      <state_interface name="position"/>
    </joint>
    <joint name="rear_right_wheel_joint">
      <command_interface name="velocity"/>
      <state_interface name="velocity"/>
      <state_interface name="position"/>
    </joint>

  </ros2_control>

  <!-- Gazebo plugin — only active when use_sim=true -->
  <xacro:if value="$(arg use_sim)">
    <gazebo>
      <plugin filename="gz_ros2_control-system"
              name="gz_ros2_control::GazeboSimROS2ControlPlugin">
        <parameters>$(find robot_bringup)/config/ros2_controllers.yaml</parameters>
        <ros>
          <remapping>/diff_drive_controller/cmd_vel:=/cmd_vel</remapping>
          <remapping>/diff_drive_controller/odom:=/odom</remapping>
        </ros>
      </plugin>
    </gazebo>
  </xacro:if>

</robot>
